2021-01-10 14:54:22,981 ERROR: Exception on /admin [GET] [in /home/apfrancis/flask/noms-dev/venv/lib/python3.6/site-packages/flask/app.py:1892]
Traceback (most recent call last):
  File "/home/apfrancis/flask/noms-dev/venv/lib/python3.6/site-packages/flask/app.py", line 2447, in wsgi_app
    response = self.full_dispatch_request()
  File "/home/apfrancis/flask/noms-dev/venv/lib/python3.6/site-packages/flask/app.py", line 1952, in full_dispatch_request
    rv = self.handle_user_exception(e)
  File "/home/apfrancis/flask/noms-dev/venv/lib/python3.6/site-packages/flask/app.py", line 1821, in handle_user_exception
    reraise(exc_type, exc_value, tb)
  File "/home/apfrancis/flask/noms-dev/venv/lib/python3.6/site-packages/flask/_compat.py", line 39, in reraise
    raise value
  File "/home/apfrancis/flask/noms-dev/venv/lib/python3.6/site-packages/flask/app.py", line 1950, in full_dispatch_request
    rv = self.dispatch_request()
  File "/home/apfrancis/flask/noms-dev/venv/lib/python3.6/site-packages/flask/app.py", line 1936, in dispatch_request
    return self.view_functions[rule.endpoint](**req.view_args)
  File "/home/apfrancis/flask/noms-dev/app/routes.py", line 15, in decorated_function
    if not session.get('email'):
NameError: name 'session' is not defined
2021-01-10 14:55:57,901 INFO: Nominations Startup [in /home/apfrancis/flask/noms-dev/app/__init__.py:48]
2021-01-10 14:56:01,504 ERROR: Exception on /admin [GET] [in /home/apfrancis/flask/noms-dev/venv/lib/python3.6/site-packages/flask/app.py:1892]
Traceback (most recent call last):
  File "/home/apfrancis/flask/noms-dev/venv/lib/python3.6/site-packages/flask/app.py", line 2447, in wsgi_app
    response = self.full_dispatch_request()
  File "/home/apfrancis/flask/noms-dev/venv/lib/python3.6/site-packages/flask/app.py", line 1952, in full_dispatch_request
    rv = self.handle_user_exception(e)
  File "/home/apfrancis/flask/noms-dev/venv/lib/python3.6/site-packages/flask/app.py", line 1821, in handle_user_exception
    reraise(exc_type, exc_value, tb)
  File "/home/apfrancis/flask/noms-dev/venv/lib/python3.6/site-packages/flask/_compat.py", line 39, in reraise
    raise value
  File "/home/apfrancis/flask/noms-dev/venv/lib/python3.6/site-packages/flask/app.py", line 1950, in full_dispatch_request
    rv = self.dispatch_request()
  File "/home/apfrancis/flask/noms-dev/venv/lib/python3.6/site-packages/flask/app.py", line 1936, in dispatch_request
    return self.view_functions[rule.endpoint](**req.view_args)
  File "/home/apfrancis/flask/noms-dev/app/routes.py", line 15, in decorated_function
    if not username.get('email'):
NameError: name 'username' is not defined
2021-01-10 14:57:19,612 INFO: Nominations Startup [in /home/apfrancis/flask/noms-dev/app/__init__.py:48]
2021-01-10 14:57:33,005 ERROR: Exception on /admin [GET] [in /home/apfrancis/flask/noms-dev/venv/lib/python3.6/site-packages/flask/app.py:1892]
Traceback (most recent call last):
  File "/home/apfrancis/flask/noms-dev/venv/lib/python3.6/site-packages/flask/app.py", line 2447, in wsgi_app
    response = self.full_dispatch_request()
  File "/home/apfrancis/flask/noms-dev/venv/lib/python3.6/site-packages/flask/app.py", line 1952, in full_dispatch_request
    rv = self.handle_user_exception(e)
  File "/home/apfrancis/flask/noms-dev/venv/lib/python3.6/site-packages/flask/app.py", line 1821, in handle_user_exception
    reraise(exc_type, exc_value, tb)
  File "/home/apfrancis/flask/noms-dev/venv/lib/python3.6/site-packages/flask/_compat.py", line 39, in reraise
    raise value
  File "/home/apfrancis/flask/noms-dev/venv/lib/python3.6/site-packages/flask/app.py", line 1950, in full_dispatch_request
    rv = self.dispatch_request()
  File "/home/apfrancis/flask/noms-dev/venv/lib/python3.6/site-packages/flask/app.py", line 1936, in dispatch_request
    return self.view_functions[rule.endpoint](**req.view_args)
  File "/home/apfrancis/flask/noms-dev/app/routes.py", line 15, in decorated_function
    if not current_user.access('email'):
TypeError: 'int' object is not callable
2021-01-10 14:57:48,393 INFO: Nominations Startup [in /home/apfrancis/flask/noms-dev/app/__init__.py:48]
2021-01-10 14:57:50,200 ERROR: Exception on /admin [GET] [in /home/apfrancis/flask/noms-dev/venv/lib/python3.6/site-packages/flask/app.py:1892]
Traceback (most recent call last):
  File "/home/apfrancis/flask/noms-dev/venv/lib/python3.6/site-packages/flask/app.py", line 2447, in wsgi_app
    response = self.full_dispatch_request()
  File "/home/apfrancis/flask/noms-dev/venv/lib/python3.6/site-packages/flask/app.py", line 1952, in full_dispatch_request
    rv = self.handle_user_exception(e)
  File "/home/apfrancis/flask/noms-dev/venv/lib/python3.6/site-packages/flask/app.py", line 1821, in handle_user_exception
    reraise(exc_type, exc_value, tb)
  File "/home/apfrancis/flask/noms-dev/venv/lib/python3.6/site-packages/flask/_compat.py", line 39, in reraise
    raise value
  File "/home/apfrancis/flask/noms-dev/venv/lib/python3.6/site-packages/flask/app.py", line 1950, in full_dispatch_request
    rv = self.dispatch_request()
  File "/home/apfrancis/flask/noms-dev/venv/lib/python3.6/site-packages/flask/app.py", line 1936, in dispatch_request
    return self.view_functions[rule.endpoint](**req.view_args)
  File "/home/apfrancis/flask/noms-dev/app/routes.py", line 15, in decorated_function
    if not current_user.access('access'):
TypeError: 'int' object is not callable
2021-01-10 14:58:13,283 INFO: Nominations Startup [in /home/apfrancis/flask/noms-dev/app/__init__.py:48]
2021-01-10 14:58:15,543 ERROR: Exception on /admin [GET] [in /home/apfrancis/flask/noms-dev/venv/lib/python3.6/site-packages/flask/app.py:1892]
Traceback (most recent call last):
  File "/home/apfrancis/flask/noms-dev/venv/lib/python3.6/site-packages/flask/app.py", line 2447, in wsgi_app
    response = self.full_dispatch_request()
  File "/home/apfrancis/flask/noms-dev/venv/lib/python3.6/site-packages/flask/app.py", line 1952, in full_dispatch_request
    rv = self.handle_user_exception(e)
  File "/home/apfrancis/flask/noms-dev/venv/lib/python3.6/site-packages/flask/app.py", line 1821, in handle_user_exception
    reraise(exc_type, exc_value, tb)
  File "/home/apfrancis/flask/noms-dev/venv/lib/python3.6/site-packages/flask/_compat.py", line 39, in reraise
    raise value
  File "/home/apfrancis/flask/noms-dev/venv/lib/python3.6/site-packages/flask/app.py", line 1950, in full_dispatch_request
    rv = self.dispatch_request()
  File "/home/apfrancis/flask/noms-dev/venv/lib/python3.6/site-packages/flask/app.py", line 1936, in dispatch_request
    return self.view_functions[rule.endpoint](**req.view_args)
  File "/home/apfrancis/flask/noms-dev/app/routes.py", line 15, in decorated_function
    if not int(current_user.access('access')):
TypeError: 'int' object is not callable
2021-01-10 15:00:26,931 INFO: Nominations Startup [in /home/apfrancis/flask/noms-dev/app/__init__.py:48]
2021-01-10 15:00:30,034 ERROR: Exception on /admin [GET] [in /home/apfrancis/flask/noms-dev/venv/lib/python3.6/site-packages/flask/app.py:1892]
Traceback (most recent call last):
  File "/home/apfrancis/flask/noms-dev/venv/lib/python3.6/site-packages/flask/app.py", line 2447, in wsgi_app
    response = self.full_dispatch_request()
  File "/home/apfrancis/flask/noms-dev/venv/lib/python3.6/site-packages/flask/app.py", line 1952, in full_dispatch_request
    rv = self.handle_user_exception(e)
  File "/home/apfrancis/flask/noms-dev/venv/lib/python3.6/site-packages/flask/app.py", line 1821, in handle_user_exception
    reraise(exc_type, exc_value, tb)
  File "/home/apfrancis/flask/noms-dev/venv/lib/python3.6/site-packages/flask/_compat.py", line 39, in reraise
    raise value
  File "/home/apfrancis/flask/noms-dev/venv/lib/python3.6/site-packages/flask/app.py", line 1950, in full_dispatch_request
    rv = self.dispatch_request()
  File "/home/apfrancis/flask/noms-dev/venv/lib/python3.6/site-packages/flask/app.py", line 1936, in dispatch_request
    return self.view_functions[rule.endpoint](**req.view_args)
  File "/home/apfrancis/flask/noms-dev/app/routes.py", line 16, in decorated_function
    return redirect(url_for('users.login'))
  File "/home/apfrancis/flask/noms-dev/venv/lib/python3.6/site-packages/flask/helpers.py", line 370, in url_for
    return appctx.app.handle_url_build_error(error, endpoint, values)
  File "/home/apfrancis/flask/noms-dev/venv/lib/python3.6/site-packages/flask/app.py", line 2216, in handle_url_build_error
    reraise(exc_type, exc_value, tb)
  File "/home/apfrancis/flask/noms-dev/venv/lib/python3.6/site-packages/flask/_compat.py", line 39, in reraise
    raise value
  File "/home/apfrancis/flask/noms-dev/venv/lib/python3.6/site-packages/flask/helpers.py", line 358, in url_for
    endpoint, values, method=method, force_external=external
  File "/home/apfrancis/flask/noms-dev/venv/lib/python3.6/site-packages/werkzeug/routing.py", line 2179, in build
    raise BuildError(endpoint, values, method, self)
werkzeug.routing.BuildError: Could not build url for endpoint 'users.login'. Did you mean 'login' instead?
