2021-01-10 17:11:22,252 ERROR: Exception on /login [POST] [in /home/apfrancis/flask/noms-dev/venv/lib/python3.6/site-packages/flask/app.py:1892]
Traceback (most recent call last):
  File "/home/apfrancis/flask/noms-dev/venv/lib/python3.6/site-packages/flask/app.py", line 2447, in wsgi_app
    response = self.full_dispatch_request()
  File "/home/apfrancis/flask/noms-dev/venv/lib/python3.6/site-packages/flask/app.py", line 1952, in full_dispatch_request
    rv = self.handle_user_exception(e)
  File "/home/apfrancis/flask/noms-dev/venv/lib/python3.6/site-packages/flask/app.py", line 1821, in handle_user_exception
    reraise(exc_type, exc_value, tb)
  File "/home/apfrancis/flask/noms-dev/venv/lib/python3.6/site-packages/flask/_compat.py", line 39, in reraise
    raise value
  File "/home/apfrancis/flask/noms-dev/venv/lib/python3.6/site-packages/flask/app.py", line 1950, in full_dispatch_request
    rv = self.dispatch_request()
  File "/home/apfrancis/flask/noms-dev/venv/lib/python3.6/site-packages/flask/app.py", line 1936, in dispatch_request
    return self.view_functions[rule.endpoint](**req.view_args)
  File "/home/apfrancis/flask/noms-dev/app/routes.py", line 49, in login
    if user is None or not user.check_password(form.password.data):
AttributeError: 'function' object has no attribute 'check_password'
2021-01-10 17:11:49,223 INFO: Nominations Startup [in /home/apfrancis/flask/noms-dev/app/__init__.py:48]
2021-01-10 17:11:54,481 ERROR: Exception on /login [POST] [in /home/apfrancis/flask/noms-dev/venv/lib/python3.6/site-packages/flask/app.py:1892]
Traceback (most recent call last):
  File "/home/apfrancis/flask/noms-dev/venv/lib/python3.6/site-packages/flask/app.py", line 2447, in wsgi_app
    response = self.full_dispatch_request()
  File "/home/apfrancis/flask/noms-dev/venv/lib/python3.6/site-packages/flask/app.py", line 1952, in full_dispatch_request
    rv = self.handle_user_exception(e)
  File "/home/apfrancis/flask/noms-dev/venv/lib/python3.6/site-packages/flask/app.py", line 1821, in handle_user_exception
    reraise(exc_type, exc_value, tb)
  File "/home/apfrancis/flask/noms-dev/venv/lib/python3.6/site-packages/flask/_compat.py", line 39, in reraise
    raise value
  File "/home/apfrancis/flask/noms-dev/venv/lib/python3.6/site-packages/flask/app.py", line 1950, in full_dispatch_request
    rv = self.dispatch_request()
  File "/home/apfrancis/flask/noms-dev/venv/lib/python3.6/site-packages/flask/app.py", line 1936, in dispatch_request
    return self.view_functions[rule.endpoint](**req.view_args)
  File "/home/apfrancis/flask/noms-dev/app/routes.py", line 49, in login
    if user is None or not user.check_password(form.password.data):
AttributeError: 'function' object has no attribute 'check_password'
2021-01-10 17:12:18,685 INFO: Nominations Startup [in /home/apfrancis/flask/noms-dev/app/__init__.py:48]
2021-01-10 17:12:22,714 ERROR: Exception on /login [POST] [in /home/apfrancis/flask/noms-dev/venv/lib/python3.6/site-packages/flask/app.py:1892]
Traceback (most recent call last):
  File "/home/apfrancis/flask/noms-dev/venv/lib/python3.6/site-packages/flask/app.py", line 2447, in wsgi_app
    response = self.full_dispatch_request()
  File "/home/apfrancis/flask/noms-dev/venv/lib/python3.6/site-packages/flask/app.py", line 1952, in full_dispatch_request
    rv = self.handle_user_exception(e)
  File "/home/apfrancis/flask/noms-dev/venv/lib/python3.6/site-packages/flask/app.py", line 1821, in handle_user_exception
    reraise(exc_type, exc_value, tb)
  File "/home/apfrancis/flask/noms-dev/venv/lib/python3.6/site-packages/flask/_compat.py", line 39, in reraise
    raise value
  File "/home/apfrancis/flask/noms-dev/venv/lib/python3.6/site-packages/flask/app.py", line 1950, in full_dispatch_request
    rv = self.dispatch_request()
  File "/home/apfrancis/flask/noms-dev/venv/lib/python3.6/site-packages/flask/app.py", line 1936, in dispatch_request
    return self.view_functions[rule.endpoint](**req.view_args)
  File "/home/apfrancis/flask/noms-dev/app/routes.py", line 49, in login
    user = User.find_by_email(session['email'])
AttributeError: type object 'User' has no attribute 'find_by_email'
2021-01-10 17:12:38,467 INFO: Nominations Startup [in /home/apfrancis/flask/noms-dev/app/__init__.py:48]
2021-01-10 17:12:46,815 ERROR: Exception on /login [GET] [in /home/apfrancis/flask/noms-dev/venv/lib/python3.6/site-packages/flask/app.py:1892]
Traceback (most recent call last):
  File "/home/apfrancis/flask/noms-dev/venv/lib/python3.6/site-packages/flask/app.py", line 2447, in wsgi_app
    response = self.full_dispatch_request()
  File "/home/apfrancis/flask/noms-dev/venv/lib/python3.6/site-packages/flask/app.py", line 1952, in full_dispatch_request
    rv = self.handle_user_exception(e)
  File "/home/apfrancis/flask/noms-dev/venv/lib/python3.6/site-packages/flask/app.py", line 1821, in handle_user_exception
    reraise(exc_type, exc_value, tb)
  File "/home/apfrancis/flask/noms-dev/venv/lib/python3.6/site-packages/flask/_compat.py", line 39, in reraise
    raise value
  File "/home/apfrancis/flask/noms-dev/venv/lib/python3.6/site-packages/flask/app.py", line 1950, in full_dispatch_request
    rv = self.dispatch_request()
  File "/home/apfrancis/flask/noms-dev/venv/lib/python3.6/site-packages/flask/app.py", line 1936, in dispatch_request
    return self.view_functions[rule.endpoint](**req.view_args)
  File "/home/apfrancis/flask/noms-dev/app/routes.py", line 59, in login
    return render_template('login.html', title='Sign In', form=form, user=user)
UnboundLocalError: local variable 'user' referenced before assignment
2021-01-10 17:12:47,543 ERROR: Exception on /login [GET] [in /home/apfrancis/flask/noms-dev/venv/lib/python3.6/site-packages/flask/app.py:1892]
Traceback (most recent call last):
  File "/home/apfrancis/flask/noms-dev/venv/lib/python3.6/site-packages/flask/app.py", line 2447, in wsgi_app
    response = self.full_dispatch_request()
  File "/home/apfrancis/flask/noms-dev/venv/lib/python3.6/site-packages/flask/app.py", line 1952, in full_dispatch_request
    rv = self.handle_user_exception(e)
  File "/home/apfrancis/flask/noms-dev/venv/lib/python3.6/site-packages/flask/app.py", line 1821, in handle_user_exception
    reraise(exc_type, exc_value, tb)
  File "/home/apfrancis/flask/noms-dev/venv/lib/python3.6/site-packages/flask/_compat.py", line 39, in reraise
    raise value
  File "/home/apfrancis/flask/noms-dev/venv/lib/python3.6/site-packages/flask/app.py", line 1950, in full_dispatch_request
    rv = self.dispatch_request()
  File "/home/apfrancis/flask/noms-dev/venv/lib/python3.6/site-packages/flask/app.py", line 1936, in dispatch_request
    return self.view_functions[rule.endpoint](**req.view_args)
  File "/home/apfrancis/flask/noms-dev/app/routes.py", line 59, in login
    return render_template('login.html', title='Sign In', form=form, user=user)
UnboundLocalError: local variable 'user' referenced before assignment
2021-01-10 17:12:50,696 INFO: Nominations Startup [in /home/apfrancis/flask/noms-dev/app/__init__.py:48]
2021-01-10 17:12:52,149 ERROR: Exception on /login [GET] [in /home/apfrancis/flask/noms-dev/venv/lib/python3.6/site-packages/flask/app.py:1892]
Traceback (most recent call last):
  File "/home/apfrancis/flask/noms-dev/venv/lib/python3.6/site-packages/flask/app.py", line 2447, in wsgi_app
    response = self.full_dispatch_request()
  File "/home/apfrancis/flask/noms-dev/venv/lib/python3.6/site-packages/flask/app.py", line 1952, in full_dispatch_request
    rv = self.handle_user_exception(e)
  File "/home/apfrancis/flask/noms-dev/venv/lib/python3.6/site-packages/flask/app.py", line 1821, in handle_user_exception
    reraise(exc_type, exc_value, tb)
  File "/home/apfrancis/flask/noms-dev/venv/lib/python3.6/site-packages/flask/_compat.py", line 39, in reraise
    raise value
  File "/home/apfrancis/flask/noms-dev/venv/lib/python3.6/site-packages/flask/app.py", line 1950, in full_dispatch_request
    rv = self.dispatch_request()
  File "/home/apfrancis/flask/noms-dev/venv/lib/python3.6/site-packages/flask/app.py", line 1936, in dispatch_request
    return self.view_functions[rule.endpoint](**req.view_args)
  File "/home/apfrancis/flask/noms-dev/app/routes.py", line 59, in login
    return render_template('login.html', title='Sign In', form=form, user=user)
UnboundLocalError: local variable 'user' referenced before assignment
2021-01-10 17:13:04,743 INFO: Nominations Startup [in /home/apfrancis/flask/noms-dev/app/__init__.py:48]
2021-01-10 17:34:22,077 INFO: Nominations Startup [in /home/apfrancis/flask/noms-dev/app/__init__.py:48]
2021-01-10 17:35:13,629 INFO: Nominations Startup [in /home/apfrancis/flask/noms-dev/app/__init__.py:48]
